{
  "timestamp": "2025-06-17T18:53:46.913613",
  "tests": {
    "database": {
      "jsonb_query": {
        "time": 0.011829137802124023,
        "rows": 0,
        "status": "WARN"
      },
      "vector_similarity": {
        "time": 2.1283624172210693,
        "rows": 10,
        "avg_similarity": 1.0,
        "status": "WARN"
      },
      "view_mv_scar_patterns": {
        "time": 0.001237630844116211,
        "rows": 2,
        "status": "PASS"
      },
      "view_mv_geoid_complexity": {
        "time": 0.0010640621185302734,
        "rows": 33,
        "status": "PASS"
      },
      "similarity_function": {
        "time": 0.002327442169189453,
        "results": 2,
        "status": "PASS"
      }
    },
    "api": {
      "/system/health": {
        "status": "FAIL",
        "error": "HTTPConnectionPool(host='localhost', port=8001): Max retries exceeded with url: /system/health (Caused by ConnectTimeoutError(<urllib3.connection.HTTPConnection object at 0x000001D37F3327B0>, 'Connection to localhost timed out. (connect timeout=1)'))"
      },
      "/system/health/detailed": {
        "status": "FAIL",
        "error": "HTTPConnectionPool(host='localhost', port=8001): Max retries exceeded with url: /system/health/detailed (Caused by NewConnectionError('<urllib3.connection.HTTPConnection object at 0x000001D37F2BBB10>: Failed to establish a new connection: [WinError 10061] No connection could be made because the target machine actively refused it'))"
      },
      "/system/status": {
        "status": "FAIL",
        "error": "HTTPConnectionPool(host='localhost', port=8001): Max retries exceeded with url: /system/status (Caused by NewConnectionError('<urllib3.connection.HTTPConnection object at 0x000001D37F2BB610>: Failed to establish a new connection: [WinError 10061] No connection could be made because the target machine actively refused it'))"
      },
      "/monitoring/status": {
        "status": "FAIL",
        "error": "HTTPConnectionPool(host='localhost', port=8001): Max retries exceeded with url: /monitoring/status (Caused by NewConnectionError('<urllib3.connection.HTTPConnection object at 0x000001D37F335E00>: Failed to establish a new connection: [WinError 10061] No connection could be made because the target machine actively refused it'))"
      },
      "geoid_creation": {
        "status": "FAIL",
        "status_code": 500
      }
    },
    "concurrent": {
      "database_concurrent": {
        "queries": 100,
        "total_time": 0.09698081016540527,
        "qps": 1031.1318273114584,
        "avg_query_time": 0.0035917043685913088,
        "status": "PASS"
      },
      "api_concurrent": {
        "requests": 50,
        "successful": 50,
        "total_time": 10.322529077529907,
        "rps": 4.8437741976276,
        "status": "PASS"
      }
    },
    "integrity": {
      "geoids_vectors": {
        "total": 33,
        "correct_dimension": 33,
        "null_vectors": 0,
        "status": "PASS"
      },
      "scars_vectors": {
        "total": 521,
        "correct_dimension": 521,
        "null_vectors": 0,
        "status": "PASS"
      },
      "jsonb_integrity": {
        "total": 33,
        "valid_symbolic": 33,
        "valid_metadata": 33,
        "status": "PASS"
      }
    }
  },
  "performance_metrics": {
    "database_performance": "EXCELLENT",
    "api_performance": "EXCELLENT",
    "concurrent_performance": "EXCELLENT",
    "data_integrity": "EXCELLENT",
    "overall": "NEEDS ATTENTION"
  },
  "errors": [],
  "pass_rate": 0.5333333333333333
}